Workbook
Name ツ: '月間 '!$X$21
Name 祝日リスト: マスタ!$C$5:$C$25
Name 津: '月間 '!#REF!

Sheet 月間 
A1: 若林運送㈱ | E1: 2026 | H1: 年 | I1: 46023 | L1: 月 | M1: 休日出勤予定表 | U1: 45664 | Y1: 時点 | AC1: 凡例 | AD1: 社休 | AE1: 法定 | AF1: 祝日 | AJ1: 若林 | AL1: クレハ
A2: ＊ 毎週 水曜までに翌月のおおよその出勤できない日（ ✕ ）を記入してください。 | Y2: 乗務員からのクレハ運輸㈱の配車調整は原則行わないこと。
A4: ※ 休日予定を配車で入れました。 ★ 必要な休日変更は、修正記載し配車へ連絡をお願いします。 | Y4: ＊｢荷卸しのみ｣､｢出荷なし｣､｢発注なし｣､｢宵済みのみ｣を稼働日カウント
Y7: ＊ 毎週の調整は、木曜日ＡＭに再報告します。
Y8: ＊ 翌月の休日予定は最終週の木曜ＡＭに報告する。
A9: 氏名 | C9: 薬品 | D9: =I1 -> 46023 | E9: =D9+1 -> 46024 | F9: =E9+1 -> 46025 | G9: =F9+1 -> 46026 | H9: =G9+1 -> 46027 | I9: =H9+1 -> 46028 | J9: =I9+1 -> 46029 | K9: =J9+1 -> 46030 | L9: =K9+1 -> 46031 | ... AH9: =AG9+1 -> 46053 | AI9: 備 考 | AJ9: 出勤可 | AK9: 休車 休日 | AL9: 稼働 | AM9: 読替休日
D10: =TEXT(D9," aaa") -> 木 | E10: =TEXT(E9,"aaa") -> 金 | F10: =TEXT(F9,"aaa") -> 土 | G10: =TEXT(G9,"aaa") -> 日 | H10: =TEXT(H9,"aaa") -> 月 | I10: =TEXT(I9,"aaa") -> 火 | J10: =TEXT(J9,"aaa") -> 水 | K10: =TEXT(K9,"aaa") -> 木 | L10: =TEXT(L9,"aaa") -> 金 | ... AH10: =TEXT(AH9,"aaa") -> 土
A11: 18 | D11: ✕ | E11: ✕ | G11: ✕ | K11: 鵜沼 | M11: ✕ | AA11: ✕ | AJ11: =マスタ!$E$6-'月間 '!AK11 -> 26 | AK11: =COUNTIFS(D11:AH11,"✕")+COUNTIFS(D11:AH11,"修理")+COUNTIFS(D11:AH11,"研修")+COUNTIFS(D11:AH11,"✖")+COUNTIFS(D11:AH11,"更新")+COUNTIFS(D11:AH11,"賃貸")+COUNTIFS(D11:AH11,"準備中") -> 5 | AL11: =AJ11+AM11 -> 26 | AM11: =COUNTIFS(D11:AH11,"✖") -> 0
A12: 1589 | D12: ✕ | F12: ✕ | H12: 鵜沼 | L12: 渡邊(浩) | M12: 渡邊(浩) | N12: ✕ | O12: 鵜沼 | P12: 渡邊(浩) | S12: 鵜沼 | AA12: 渡邊 | AB12: ✕ | AJ12: =マスタ!$E$6-'月間 '!AK12 -> 27 | AK12: =COUNTIFS(D12:AH12,"✕")+COUNTIFS(D12:AH12,"修理")+COUNTIFS(D12:AH12,"研修")+COUNTIFS(D12:AH12,"✖")+COUNTIFS(D12:AH12,"更新")+COUNTIFS(D12:AH12,"賃貸")+COUNTIFS(D12:AH12,"準備中") -> 4 | AL12: =AJ12+AM12 -> 27 | AM12: =COUNTIFS(D12:AH12,"✖") -> 0
A13: 1116 | D13: ✕ | E13: ✕ | F13: ✕ | N13: ✕ | AB13: ✕ | AJ13: =マスタ!$E$6-'月間 '!AK13 -> 26 | AK13: =COUNTIFS(D13:AH13,"✕")+COUNTIFS(D13:AH13,"修理")+COUNTIFS(D13:AH13,"研修")+COUNTIFS(D13:AH13,"✖")+COUNTIFS(D13:AH13,"更新")+COUNTIFS(D13:AH13,"賃貸")+COUNTIFS(D13:AH13,"準備中") -> 5 | AL13: =AJ13+AM13 -> 26 | AM13: =COUNTIFS(D13:AH13,"✖") -> 0
A14: 【係長】鈴木 浩明 | C14: 塩酸 | D14: ✕ | E14: ✕ | F14: 18 | G14: ✕ | H14: 18 | I14: 18 | J14: 18 | K14: 巡回 | L14: 18 | M14: ✕ | N14: 18 | O14: 18 | P14: 18 | Q14: 18 | R14: 18 | S14: 18 | V14: 18 | W14: 18 | X14: 巡回 | Y14: 18 | Z14: 18 | AA14: ✕ | AB14: 18 | AI14: 1/9係長・班長会議 | AJ14: =マスタ!$E$6-'月間 '!AK14 -> 26 | AK14: =COUNTIFS(C14:AH14,"✕")+COUNTIFS(C14:AH14,"修理")+COUNTIFS(C14:AH14,"車検")+COUNTIFS(C14:AH14,"研修")+COUNTIFS(D13:AH13,"✖") -> 5
A15: 【700】渡邉 進一 | C15: 塩酸 苛性 | D15: ✕ | E15: 1589 | F15: 700 | G15: 1589 | H15: 700 | I15: 1589 | J15: 1589 | K15: 1589 | L15: 700 | M15: 700 | N15: ✕ | O15: 643 | P15: 700 | Q15: 1589 | R15: 1589 | S15: ✕ | T15: 700 | U15: ✕ | V15: 1589 | W15: 700 | X15: 700 | Y15: 1589 | Z15: 1589 | AA15: 700 | AB15: ✕ | AI15: 1/9以降見極め(金山室長)/1/13見極め | AJ15: =マスタ!$E$6-'月間 '!AK15 -> 26 | AK15: =COUNTIFS(C15:AH15,"✕")+COUNTIFS(C15:AH15,"修理")+COUNTIFS(C15:AH15,"車検")+COUNTIFS(C15:AH15,"研修")+COUNTIFS(D15:AH15,"✖") -> 5
A16: 山口 豊 | C16: 塩酸 | D16: ✕ | E16: ✕ | F16: ✕ | G16: 1116 | H16: 1116 | I16: 1116 | J16: 1116 | K16: 1116 | L16: 1116 | M16: 1116 | N16: ✕ | O16: 1116 | P16: 1116 | Q16: 1116 | R16: 1116 | S16: 1116 | V16: 1116 | W16: 1116 | X16: 1116 | Y16: 1116 | Z16: 1116 | AA16: 1116 | AB16: ✕ | AC16: 1116 | AD16: 1116 | AE16: 1116 | AF16: 1116 | AG16: 1116 | AH16: 1116 | AJ16: =マスタ!$E$6-'月間 '!AK16 -> 26 | AK16: =COUNTIFS(C16:AH16,"✕")+COUNTIFS(C16:AH16,"修理")+COUNTIFS(C16:AH16,"車検")+COUNTIFS(C16:AH16,"研修")+COUNTIFS(D15:AH15,"✖") -> 5
A18: 【班長】味戸 隆典 | C18: 苛性 | D18: ✕ | E18: ✕ | F18: ✕ | G18: ✕ | H18: 700 | I18: 700 | J18: 700 | K18: 700 | L18: 700 | M18: 700 | N18: ✕ | O18: 643 | P18: 700 | Q18: 700 | R18: 700 | S18: 700 | T18: 700 | U18: ✕ | V18: 700 | W18: 700 | X18: 700 | Y18: 700 | Z18: 700 | AA18: 700 | AB18: ✕ | AI18: 1/8係長・班長会議 | AJ18: =マスタ!$E$6-'月間 '!AK18 -> 24 | AK18: =COUNTIFS(C18:AH18,"✕")+COUNTIFS(C18:AH18,"修理")+COUNTIFS(C18:AH18,"車検")+COUNTIFS(C18:AH18,"研修")+COUNTIFS(D17:AH17,"✖") -> 7
A19: 【3640】小林 啓一 | C19: 苛性 | D19: ✕ | E19: ✕ | F19: ✕ | G19: ✕ | H19: ✕ | I19: 3640 | J19: 3640 | K19: 3640 | L19: 3640 | M19: 3640 | N19: ✕ | O19: 3640 | P19: 3640 | Q19: 3640 | R19: 3640 | S19: 3640 | T19: ✕ | U19: 3640 | V19: 3640 | W19: 3640 | X19: 3640 | Y19: 3640 | Z19: 3640 | AA19: 3640 | AB19: ✕ | AI19: 1/5日通院 | AJ19: =マスタ!$E$6-'月間 '!AK19 -> 23 | AK19: =COUNTIFS(C19:AH19,"✕")+COUNTIFS(C19:AH19,"修理")+COUNTIFS(C19:AH19,"車検")+COUNTIFS(C19:AH19,"研修")+COUNTIFS(D18:AH18,"✖") -> 8
A20: 【1693】鈴木 富雄 | C20: 苛性 | AJ20: =マスタ!$E$6-'月間 '!AK20 -> 31 | AK20: =COUNTIFS(C20:AH20,"✕")+COUNTIFS(C20:AH20,"修理")+COUNTIFS(C20:AH20,"車検")+COUNTIFS(C20:AH20,"研修")+COUNTIFS(D19:AH19,"✖") -> 0
A21: 【3640】大平 正勝 | C21: 苛性 | D21: ✕ | E21: ✕ | F21: ✕ | G21: ✕ | H21: ✕ | I21: ✕ | J21: ✕ | K21: ✕ | L21: ✕ | M21: ✕ | N21: ✕ | O21: ✕ | P21: ✕ | Q21: ✕ | R21: ✕ | S21: ✕ | T21: ✕ | U21: ✕ | V21: ✕ | W21: ✕ | X21: ✕ | Y21: ✕ | Z21: ✕ | AA21: ✕ | AB21: ✕ | AC21: ✕ | AD21: ✕ | AE21: ✕ | AF21: ✕ | AG21: ✕ | AH21: ✕ | AI21: 眼病療養中 | AJ21: =マスタ!$E$6-'月間 '!AK21 -> 0 | AK21: =COUNTIFS(C21:AH21,"✕")+COUNTIFS(C21:AH21,"修理")+COUNTIFS(C21:AH21,"車検")+COUNTIFS(C21:AH21,"研修")+COUNTIFS(D20:AH20,"✖") -> 31
A22: 【2401】荒木 正朋 | C22: 苛性 | D22: ✕ | E22: ✕ | F22: 2401 | G22: ✕ | H22: 2401 | I22: 2401 | J22: 2401 | K22: 2401 | L22: 2401 | M22: ✕ | N22: 2401 | O22: 2401 | P22: 2401 | Q22: 2401 | R22: 2401 | S22: 2401 | T22: 2401 | U22: ✕ | V22: 2401 | W22: 2401 | X22: 2401 | Y22: 2401 | Z22: 2401 | AA22: ✕ | AB22: 2401 | AJ22: =マスタ!$E$6-'月間 '!AK22 -> 25 | AK22: =COUNTIFS(C22:AH22,"✕")+COUNTIFS(C22:AH22,"修理")+COUNTIFS(C22:AH22,"車検")+COUNTIFS(C22:AH22,"研修")+COUNTIFS(D21:AH21,"✖") -> 6
A23: 吉田 哲司 | C23: 苛性 | D23: ✕ | E23: 19 | F23: ✕ | G23: 19 | H23: 3640 | I23: 19 | J23: 19 | K23: 19 | L23: 19 | M23: 1136 | N23: 384 | O23: 384 | P23: 384 | Q23: 384 | R23: 384 | S23: 384 | T23: ✕ | U23: 384 | V23: 384 | W23: 384 | X23: 384 | Y23: 384 | Z23: 384 | AA23: 384 | AB23: ✕ | AJ23: =マスタ!$E$6-'月間 '!AK23 -> 27 | AK23: =COUNTIFS(C23:AH23,"✕")+COUNTIFS(C23:AH23,"修理")+COUNTIFS(C23:AH23,"車検")+COUNTIFS(C23:AH23,"研修")+COUNTIFS(D22:AH22,"✖") -> 4
A24: 菊地 秀和 | C24: 苛性 | D24: ✕ | E24: 384 | F24: 384 | G24: ✕ | H24: ✕ | I24: 整備 | J24: 643 | L24: 384 | M24: 384 | N24: ✕ | O24: 19 | P24: 19 | Q24: 19 | R24: 19 | S24: 19 | T24: ✕ | U24: 19 | V24: 19 | W24: 19 | X24: 19 | Y24: 19 | Z24: 19 | AA24: ✕ | AB24: 384 | AI24: 1/5通院 | AJ24: =マスタ!$E$6-'月間 '!AK24 -> 25 | AK24: =COUNTIFS(C24:AH24,"✕")+COUNTIFS(C24:AH24,"修理")+COUNTIFS(C24:AH24,"車検")+COUNTIFS(C24:AH24,"研修")+COUNTIFS(D23:AH23,"✖") -> 6
A25: 齋藤 健一 | C25: 苛性 ﾊﾞﾝﾄﾞ油 | D25: ✕ | E25: 1136 | F25: 1170 | G25: ✕ | H25: 1136 | I25: 1170 | J25: 1170 | K25: 1136 | L25: 1136 | M25: ✕ | N25: 530 | O25: 1170 | P25: 643 | Q25: 1170 | R25: 1170 | S25: 1170 | T25: 1170 | U25: ✕ | V25: 1170 | W25: 643 | X25: 643 | Y25: 643 | Z25: 643 | AA25: ✕ | AB25: 643 | AJ25: =マスタ!$E$6-'月間 '!AK25 -> 26 | AK25: =COUNTIFS(C25:AH25,"✕")+COUNTIFS(C25:AH25,"修理")+COUNTIFS(C25:AH25,"車検")+COUNTIFS(C25:AH25,"研修")+COUNTIFS(D24:AH24,"✖") -> 5
A26: 松本 誠治 | C26: 苛性 ﾊﾞﾝﾄﾞ油 | D26: ✕ | E26: ✕ | F26: 1136 | G26: 643 | H26: 643 | I26: 643 | J26: ✕ | K26: 643 | L26: 643 | M26: 1170 | N26: 1136 | O26: ✕ | P26: 1136 | Q26: 1136 | R26: 1136 | S26: 1136 | T26: ✕ | U26: 1136 | V26: 1136 | W26: 1136 | X26: 1136 | Y26: 1170 | Z26: 1170 | AA26: 1170 | AB26: ✕ | AJ26: =マスタ!$E$6-'月間 '!AK26 -> 25 | AK26: =COUNTIFS(C26:AH26,"✕")+COUNTIFS(C26:AH26,"修理")+COUNTIFS(C26:AH26,"車検")+COUNTIFS(C26:AH26,"研修")+COUNTIFS(D25:AH25,"✖") -> 6
A27: 【班長】渡邊 浩司 | C27: 全種 | D27: ✕ | E27: ✕ | F27: 700 | G27: ✕ | H27: 19 | I27: 1136 | J27: 1136 | K27: 巡回 | L27: 1589 | M27: 1589 | N27: 700 | O27: ✕ | P27: 1589 | Q27: 643 | R27: 643 | S27: 643 | T27: 643 | U27: ✕ | V27: 643 | W27: 1589 | X27: 1589 | Y27: 1136 | Z27: 1136 | AA27: 1589 | AB27: ✕ | AI27: 1/8係長・班長会議 | AJ27: =マスタ!$E$6-'月間 '!AK27 -> 25 | AK27: =COUNTIFS(C27:AH27,"✕")+COUNTIFS(C27:AH27,"修理")+COUNTIFS(C27:AH27,"車検")+COUNTIFS(C27:AH27,"研修")+COUNTIFS(D26:AH26,"✖") -> 6
AJ28: =マスタ!$E$6-'月間 '!AK28 -> 31 | AK28: =COUNTIFS(C28:AH28,"✕")+COUNTIFS(C28:AH28,"修理")+COUNTIFS(C28:AH28,"車検")+COUNTIFS(C28:AH28,"研修")+COUNTIFS(D27:AH27,"✖") -> 0
AJ29: =マスタ!$E$6-'月間 '!AK29 -> 31 | AK29: =COUNTIFS(C29:AH29,"✕")+COUNTIFS(C29:AH29,"修理")+COUNTIFS(C29:AH29,"車検")+COUNTIFS(C29:AH29,"研修")+COUNTIFS(D28:AH28,"✖") -> 0
A30: 700 | D30: ✕ | E30: ✕ | G30: ✕ | O30: ✕ | U30: ✕ | AB30: ✕ | AJ30: =マスタ!$E$6-'月間 '!AK30 -> 25 | AK30: =COUNTIFS(D30:AH30,"✕")+COUNTIFS(D30:AH30,"修理")+COUNTIFS(D30:AH30,"研修")+COUNTIFS(D30:AH30,"✖")+COUNTIFS(D30:AH30,"更新") -> 6 | AL30: =AJ30+AM30 -> 25 | AM30: =COUNTIFS(D30:AH30,"✖") -> 0
A31: 1693 | AJ31: =マスタ!$E$6-'月間 '!AK31 -> 31 | AK31: =COUNTIFS(D31:AH31,"✕")+COUNTIFS(D31:AH31,"修理")+COUNTIFS(D31:AH31,"研修")+COUNTIFS(D31:AH31,"✖")+COUNTIFS(D31:AH31,"更新") -> 0 | AL31: =AJ31+AM31 -> 31 | AM31: =COUNTIFS(D31:AH31,"✖") -> 0
A32: 3640 | D32: ✕ | E32: ✕ | F32: ✕ | G32: ✕ | N32: ✕ | T32: ✕ | AB32: ✕ | AJ32: =マスタ!$E$6-'月間 '!AK32 -> 24 | AK32: =COUNTIFS(D32:AH32,"✕")+COUNTIFS(D32:AH32,"修理")+COUNTIFS(D32:AH32,"研修")+COUNTIFS(D32:AH32,"✖")+COUNTIFS(D32:AH32,"更新") -> 7 | AL32: =AJ32+AM32 -> 24 | AM32: =COUNTIFS(D32:AH32,"✖") -> 0
A33: 643 | D33: ✕ | E33: ✕ | F33: ✕ | M33: ✕ | N33: ✕ | U33: ✕ | AA33: ✕ | AJ33: =マスタ!$E$6-'月間 '!AK33 -> 24 | AK33: =COUNTIFS(D33:AH33,"✕")+COUNTIFS(D33:AH33,"修理")+COUNTIFS(D33:AH33,"研修")+COUNTIFS(D33:AH33,"✖")+COUNTIFS(D33:AH33,"更新") -> 7 | AL33: =AJ33+AM33 -> 24 | AM33: =COUNTIFS(D33:AH33,"✖") -> 0
A34: 2401 | D34: ✕ | E34: ✕ | G34: ✕ | M34: ✕ | U34: ✕ | AA34: ✕ | AJ34: =マスタ!$E$6-'月間 '!AK34 -> 25 | AK34: =COUNTIFS(D34:AH34,"✕")+COUNTIFS(D34:AH34,"修理")+COUNTIFS(D34:AH34,"研修")+COUNTIFS(D34:AH34,"✖")+COUNTIFS(D34:AH34,"更新") -> 6 | AL34: =AJ34+AM34 -> 25 | AM34: =COUNTIFS(D34:AH34,"✖") -> 0
A35: 19 | D35: ✕ | F35: ✕ | M35: ✕ | N35: ✕ | T35: ✕ | AA35: ✕ | AB35: ✕ | AJ35: =マスタ!$E$6-'月間 '!AK35 -> 24 | AK35: =COUNTIFS(D35:AH35,"✕")+COUNTIFS(D35:AH35,"修理")+COUNTIFS(D35:AH35,"研修")+COUNTIFS(D35:AH35,"✖")+COUNTIFS(D35:AH35,"更新") -> 7 | AL35: =AJ35+AM35 -> 24 | AM35: =COUNTIFS(D35:AH35,"✖") -> 0
A36: 384 | D36: ✕ | G36: ✕ | H36: ✕ | I36: ✕ | J36: ✕ | K36: ✕ | T36: ✕ | AI36: 1/6修理点検(ｴﾝｼﾞﾝﾁｪｯｸﾗﾝﾌﾟ異常) | AJ36: =マスタ!$E$6-'月間 '!AK36 -> 24 | AK36: =COUNTIFS(D36:AH36,"✕")+COUNTIFS(D36:AH36,"修理")+COUNTIFS(D36:AH36,"研修")+COUNTIFS(D36:AH36,"✖")+COUNTIFS(D36:AH36,"更新") -> 7 | AL36: =AJ36+AM36 -> 24 | AM36: =COUNTIFS(D36:AH36,"✖") -> 0
A37: 2403 | AJ37: =マスタ!$E$6-'月間 '!AK37 -> 31 | AK37: =COUNTIFS(D37:AH37,"✕")+COUNTIFS(D37:AH37,"修理")+COUNTIFS(D37:AH37,"研修")+COUNTIFS(D37:AH37,"✖")+COUNTIFS(D37:AH37,"更新") -> 0 | AL37: =AJ37+AM37 -> 31 | AM37: =COUNTIFS(D37:AH37,"✖") -> 0
A38: 1136 | D38: ✕ | G38: ✕ | O38: ✕ | T38: ✕ | AA38: ✕ | AB38: ✕ | AJ38: =マスタ!$E$6-'月間 '!AK38 -> 25 | AK38: =COUNTIFS(D38:AH38,"✕")+COUNTIFS(D38:AH38,"修理")+COUNTIFS(D38:AH38,"研修")+COUNTIFS(D38:AH38,"✖")+COUNTIFS(D38:AH38,"更新") -> 6 | AL38: =AJ38+AM38 -> 25 | AM38: =COUNTIFS(D38:AH38,"✖") -> 0
A39: 154 | AJ39: =マスタ!$E$6-'月間 '!AK39 -> 31 | AK39: =COUNTIFS(D39:AH39,"✕")+COUNTIFS(D39:AH39,"修理")+COUNTIFS(D39:AH39,"研修")+COUNTIFS(D39:AH39,"✖")+COUNTIFS(D39:AH39,"更新") -> 0 | AL39: =AJ39+AM39 -> 31 | AM39: =COUNTIFS(D39:AH39,"✖") -> 0
A40: 1246 | D40: ✕ | F40: ✕ | G40: ✕ | N40: ✕ | U40: ✕ | AB40: ✕ | AJ40: =マスタ!$E$6-'月間 '!AK40 -> 25 | AK40: =COUNTIFS(D40:AH40,"✕")+COUNTIFS(D40:AH40,"修理")+COUNTIFS(D40:AH40,"研修")+COUNTIFS(D40:AH40,"✖")+COUNTIFS(D40:AH40,"更新") -> 6 | AL40: =AJ40+AM40 -> 25 | AM40: =COUNTIFS(D40:AH40,"✖") -> 0 | AN40: メルク② | AO40: ＪＸ | AP40: プロセス
A41: 【係長】雲藤 順 | C41: バンド 油 | D41: ✕ | E41: ✕ | F41: ✕ | G41: ✕ | H41: 1170 | I41: 530 | J41: 530 | K41: 1170 | L41: 1170 | M41: 530 | N41: ✕ | O41: ✕ | P41: 1170 | Q41: 530 | R41: 530 | S41: 巡回 | T41: ✕ | U41: 530 | V41: 530 | W41: 1170 | X41: 1170 | Y41: 530 | Z41: 530 | AA41: ✕ | AB41: 530 | AC41: 530 | AE41: 530 | AF41: 530 | AI41: 1/8係長・班長会議 | AJ41: =マスタ!$E$6-'月間 '!AK41 -> 23 | AK41: =COUNTIFS(C41:AH41,"✕")+COUNTIFS(C41:AH41,"修理")+COUNTIFS(C41:AH41,"車検")+COUNTIFS(C41:AH41,"研修")+COUNTIFS(D40:AH40,"✖") -> 8 | AO41: 15 | AP41: 3
A42: 鵜沼 芳昭 | C42: バンド 塩酸 | D42: ✕ | E42: ✕ | F42: ✕ | G42: ✕ | H42: 1589 | I42: 2501 | J42: 2501 | K42: 18 | L42: 整備 | M42: 2501 | N42: 2501 | O42: 1589 | P42: 整備 | Q42: 2501 | R42: 2501 | S42: 1589 | T42: ✕ | U42: 2501 | V42: 2501 | W42: 整備 | X42: 18 | Y42: 2501 | Z42: 2501 | AA42: ✕ | AB42: 2501 | AC42: 2501 | AE42: 2501 | AF42: 2501 | AJ42: =マスタ!$E$6-'月間 '!AK42 -> 25 | AK42: =COUNTIFS(C42:AH42,"✕")+COUNTIFS(C42:AH42,"修理")+COUNTIFS(C42:AH42,"車検")+COUNTIFS(C42:AH42,"研修")+COUNTIFS(D41:AH41,"✖") -> 6
A43: 【新人】小玉 美香 | C43: バンド | L43: 教育 | M43: 教育 | N43: ✕ | O43: ✕ | P43: 検診 適正 | Q43: 教育 | R43: 教育 | S43: 教育 | T43: ✕ | U43: 530 | V43: 530 | W43: 教育 | X43: 教育 | Y43: 530 | Z43: 530 | AA43: ✕ | AB43: 530 | AC43: 530 | AE43: 530 | AF43: 530 | AH43: ✕ | AI43: 1/9入社・1/13AM検診・PM適正 | AJ43: =マスタ!$E$6-'月間 '!AK43 -> 26 | AK43: =COUNTIFS(C43:AH43,"✕")+COUNTIFS(C43:AH43,"修理")+COUNTIFS(C43:AH43,"車検")+COUNTIFS(C43:AH43,"研修")+COUNTIFS(D42:AH42,"✖") -> 5
A44: 2501 | I44: ⑬ | J44: 13 | M44: 13 | N44: 13 | Q44: 13 | R44: 13 | U44: 13 | V44: 13 | Y44: 13 | Z44: 13 | AB44: 13 | AC44: 13 | AE44: 13 | AF44: 13 | AJ44: =マスタ!$E$6-'月間 '!AK44 -> 31 | AK44: =COUNTIFS(D44:AH44,"✕")+COUNTIFS(D44:AH44,"修理")+COUNTIFS(D44:AH44,"研修")+COUNTIFS(D44:AH44,"✖")+COUNTIFS(D44:AH44,"更新") -> 0
...

Sheet ３月月間(乗務員用）
A1: 若林運送㈱ | E1: ='月間 '!E1:G1 -> 2026 | H1: 年 | I1: ='月間 '!I1:K1 -> 46023 | L1: 月 | N1: 休日出勤予定表 | U1: ='月間 '!U1:X1 -> 45664 | Y1: 時点 | AC1: 凡例 | AD1: 社休 | AE1: 法定 | AF1: 祝日 | AI1: ='月間 '!AI1 -> 0 | AL1: クレハ
A2: ＊ 毎週 水曜までに翌月のおおよその出勤できない日（ ✕ ）を記入してください。 | Y2: 乗務員からのクレハ運輸㈱の配車調整は原則行わないこと。
A4: ※ 休日予定を配車で入れました。 ★ 必要な休日変更は、修正記載し配車へ連絡をお願いします。 | Y4: ＊｢荷卸しのみ｣､｢出荷なし｣､｢発注なし｣､｢宵済みのみ｣を稼働日カウント
Y7: ＊ 毎週の調整は、木曜日ＡＭに再報告します。
Y8: ＊ 翌月の休日予定は最終週の木曜ＡＭに報告する。
A9: 氏名 | C9: 薬品 | D9: =I1 -> 46023 | E9: =D9+1 -> 46024 | F9: =E9+1 -> 46025 | G9: =F9+1 -> 46026 | H9: =G9+1 -> 46027 | I9: =H9+1 -> 46028 | J9: =I9+1 -> 46029 | K9: =J9+1 -> 46030 | L9: =K9+1 -> 46031 | ... AH9: =AG9+1 -> 46053 | AI9: 備 考 | AJ9: 出勤可 | AK9: 休 | AL9: 稼働 | AM9: 読替分
D10: =TEXT(D9," aaa") -> 木 | E10: =TEXT(E9,"aaa") -> 金 | F10: =TEXT(F9,"aaa") -> 土 | G10: =TEXT(G9,"aaa") -> 日 | H10: =TEXT(H9,"aaa") -> 月 | I10: =TEXT(I9,"aaa") -> 火 | J10: =TEXT(J9,"aaa") -> 水 | K10: =TEXT(K9,"aaa") -> 木 | L10: =TEXT(L9,"aaa") -> 金 | ... AH10: =TEXT(AH9,"aaa") -> 土
A11: 【係長】鈴木 浩明 | C11: 塩酸 | D11: =IF('月間 '!D14="","",'月間 '!D14) -> ✕ | E11: =IF('月間 '!E14="","",'月間 '!E14) -> ✕ | F11: =IF('月間 '!F14="","",'月間 '!F14) -> 18 | G11: =IF('月間 '!G14="","",'月間 '!G14) -> ✕ | H11: =IF('月間 '!H14="","",'月間 '!H14) -> 18 | I11: =IF('月間 '!I14="","",'月間 '!I14) -> 18 | J11: =IF('月間 '!J14="","",'月間 '!J14) -> 18 | K11: =IF('月間 '!K14="","",'月間 '!K14) -> 巡回 | ... AI11: =IF('月間 '!AI14="","",'月間 '!AI14) -> 1/9係長・班長会議 | AJ11: =マスタ!$E$6-'３月月間(乗務員用）'!AK11 -> 26 | AK11: =COUNTIFS(C11:AH11,"✕")+COUNTIFS(C11:AH11,"修理")+COUNTIFS(C11:AH11,"車検")+COUNTIFS(C11:AH11,"研修") -> 5 | AL11: =AJ11+AM11 -> 26 | AM11: =COUNTIFS(D11:AH11,"✖") -> 0
A12: 【班長】鵜沼 芳昭 | C12: 塩酸 | D12: =IF('月間 '!#REF!="","",'月間 '!#REF!) -> #REF! | E12: =IF('月間 '!#REF!="","",'月間 '!#REF!) -> #REF! | F12: =IF('月間 '!#REF!="","",'月間 '!#REF!) -> #REF! | G12: =IF('月間 '!#REF!="","",'月間 '!#REF!) -> #REF! | H12: =IF('月間 '!#REF!="","",'月間 '!#REF!) -> #REF! | I12: =IF('月間 '!#REF!="","",'月間 '!#REF!) -> #REF! | J12: =IF('月間 '!#REF!="","",'月間 '!#REF!) -> #REF! | K12: =IF('月間 '!#REF!="","",'月間 '!#REF!) -> #REF! | ... AI12: =IF('月間 '!#REF!="","",'月間 '!#REF!) -> #REF! | AJ12: =マスタ!$E$6-'３月月間(乗務員用）'!AK12 -> 31 | AK12: =COUNTIFS(C12:AH12,"✕")+COUNTIFS(C12:AH12,"修理")+COUNTIFS(C12:AH12,"車検")+COUNTIFS(C12:AH12,"研修") -> 0 | AL12: =AJ12+AM12 -> 31 | AM12: =COUNTIFS(D12:AH12,"✖") -> 0
A13: 【班長】渡邊 浩司 | C13: 塩酸 | D13: =IF('月間 '!#REF!="","",'月間 '!#REF!) -> #REF! | E13: =IF('月間 '!#REF!="","",'月間 '!#REF!) -> #REF! | F13: =IF('月間 '!#REF!="","",'月間 '!#REF!) -> #REF! | G13: =IF('月間 '!#REF!="","",'月間 '!#REF!) -> #REF! | H13: =IF('月間 '!#REF!="","",'月間 '!#REF!) -> #REF! | I13: =IF('月間 '!#REF!="","",'月間 '!#REF!) -> #REF! | J13: =IF('月間 '!#REF!="","",'月間 '!#REF!) -> #REF! | K13: =IF('月間 '!#REF!="","",'月間 '!#REF!) -> #REF! | ... AI13: =IF('月間 '!#REF!="","",'月間 '!#REF!) -> #REF! | AJ13: =マスタ!$E$6-'３月月間(乗務員用）'!AK13 -> 31 | AK13: =COUNTIFS(C13:AH13,"✕")+COUNTIFS(C13:AH13,"修理")+COUNTIFS(C13:AH13,"車検")+COUNTIFS(C13:AH13,"研修") -> 0 | AL13: =AJ13+AM13 -> 31 | AM13: =COUNTIFS(D13:AH13,"✖") -> 0
A14: 渡邉 進一 | C14: 塩酸 | D14: =IF('月間 '!D15="","",'月間 '!D15) -> ✕ | E14: =IF('月間 '!E15="","",'月間 '!E15) -> 1589 | F14: =IF('月間 '!F15="","",'月間 '!F15) -> 700 | G14: =IF('月間 '!G15="","",'月間 '!G15) -> 1589 | H14: =IF('月間 '!H15="","",'月間 '!H15) -> 700 | I14: =IF('月間 '!I15="","",'月間 '!I15) -> 1589 | J14: =IF('月間 '!J15="","",'月間 '!J15) -> 1589 | K14: =IF('月間 '!K15="","",'月間 '!K15) -> 1589 | ... AI14: =IF('月間 '!AI15="","",'月間 '!AI15) -> 1/9以降見極め(金山室長)/1/13見極め | AJ14: =マスタ!$E$6-'３月月間(乗務員用）'!AK14 -> 26 | AK14: =COUNTIFS(C14:AH14,"✕")+COUNTIFS(C14:AH14,"修理")+COUNTIFS(C14:AH14,"車検")+COUNTIFS(C14:AH14,"研修") -> 5 | AL14: =AJ14+AM14 -> 26 | AM14: =COUNTIFS(D14:AH14,"✖") -> 0
A15: 齋藤 秀行 | C15: 塩酸 | D15: =IF('月間 '!D16="","",'月間 '!D16) -> ✕ | E15: =IF('月間 '!E16="","",'月間 '!E16) -> ✕ | F15: =IF('月間 '!F16="","",'月間 '!F16) -> ✕ | G15: =IF('月間 '!G16="","",'月間 '!G16) -> 1116 | H15: =IF('月間 '!H16="","",'月間 '!H16) -> 1116 | I15: =IF('月間 '!I16="","",'月間 '!I16) -> 1116 | J15: =IF('月間 '!J16="","",'月間 '!J16) -> 1116 | K15: =IF('月間 '!K16="","",'月間 '!K16) -> 1116 | ... AI15: =IF('月間 '!AI16="","",'月間 '!AI16) | AJ15: =マスタ!$E$6-'３月月間(乗務員用）'!AK15 -> 26 | AK15: =COUNTIFS(D15:AH15,"✕")+COUNTIFS(D15:AH15,"出荷無")+COUNTIFS(D15:AH15,"発注無")+COUNTIFS(D15:AH15,"修理")+COUNTIFS(D15:AH15,"車検") -> 5
A16: 【班長】小沼 康 | C16: フリー | D16: =IF('月間 '!#REF!="","",'月間 '!#REF!) -> #REF! | E16: =IF('月間 '!#REF!="","",'月間 '!#REF!) -> #REF! | F16: =IF('月間 '!#REF!="","",'月間 '!#REF!) -> #REF! | G16: =IF('月間 '!#REF!="","",'月間 '!#REF!) -> #REF! | H16: =IF('月間 '!#REF!="","",'月間 '!#REF!) -> #REF! | I16: =IF('月間 '!#REF!="","",'月間 '!#REF!) -> #REF! | J16: =IF('月間 '!#REF!="","",'月間 '!#REF!) -> #REF! | K16: =IF('月間 '!#REF!="","",'月間 '!#REF!) -> #REF! | ... AI16: =IF('月間 '!#REF!="","",'月間 '!#REF!) -> #REF! | AJ16: =マスタ!$E$6-'３月月間(乗務員用）'!AK16 -> 31 | AK16: =COUNTIFS(D16:AH16,"✕")+COUNTIFS(D16:AH16,"出荷無")+COUNTIFS(D16:AH16,"発注無")+COUNTIFS(D16:AH16,"修理")+COUNTIFS(D16:AH16,"車検") -> 0
A17: 【班長】味戸 隆典 | C17: 苛性 | D17: =IF('月間 '!D18="","",'月間 '!D18) -> ✕ | E17: =IF('月間 '!E18="","",'月間 '!E18) -> ✕ | F17: =IF('月間 '!F18="","",'月間 '!F18) -> ✕ | G17: =IF('月間 '!G18="","",'月間 '!G18) -> ✕ | H17: =IF('月間 '!H18="","",'月間 '!H18) -> 700 | I17: =IF('月間 '!I18="","",'月間 '!I18) -> 700 | J17: =IF('月間 '!J18="","",'月間 '!J18) -> 700 | K17: =IF('月間 '!K18="","",'月間 '!K18) -> 700 | ... AI17: =IF('月間 '!AI18="","",'月間 '!AI18) -> 1/8係長・班長会議 | AJ17: =マスタ!$E$6-'３月月間(乗務員用）'!AK17 -> 24 | AK17: =COUNTIFS(C17:AH17,"✕")+COUNTIFS(C17:AH17,"修理")+COUNTIFS(C17:AH17,"車検")+COUNTIFS(C17:AH17,"研修") -> 7
A18: 【700】小林 啓一 | C18: 苛性 | D18: =IF('月間 '!D19="","",'月間 '!D19) -> ✕ | E18: =IF('月間 '!E19="","",'月間 '!E19) -> ✕ | F18: =IF('月間 '!F19="","",'月間 '!F19) -> ✕ | G18: =IF('月間 '!G19="","",'月間 '!G19) -> ✕ | H18: =IF('月間 '!H19="","",'月間 '!H19) -> ✕ | I18: =IF('月間 '!P19="","",'月間 '!P19) -> 3640 | J18: =IF('月間 '!J19="","",'月間 '!J19) -> 3640 | K18: =IF('月間 '!K19="","",'月間 '!K19) -> 3640 | L18: =IF('月間 '!L19="","",'月間 '!L19) -> 3640 | M18: =IF('月間 '!M19="","",'月間 '!M19) -> 3640 | N18: =IF('月間 '!N19="","",'月間 '!N19) -> ✕ | O18: =IF('月間 '!O19="","",'月間 '!O19) -> 3640 | P18: =IF('月間 '!#REF!="","",'月間 '!#REF!) -> #REF! | Q18: =IF('月間 '!Q19="","",'月間 '!Q19) -> 3640 | R18: =IF('月間 '!R19="","",'月間 '!R19) -> 3640 | S18: =IF('月間 '!S19="","",'月間 '!S19) -> 3640 | T18: =IF('月間 '!T19="","",'月間 '!T19) -> ✕ | U18: =IF('月間 '!U19="","",'月間 '!U19) -> 3640 | V18: =IF('月間 '!V19="","",'月間 '!V19) -> 3640 | W18: =IF('月間 '!W19="","",'月間 '!W19) -> 3640 | X18: =IF('月間 '!X19="","",'月間 '!X19) -> 3640 | ... AD18: =IF('月間 '!AD19="","",'月間 '!AD19) | AE18: =IF('月間 '!AD35="","",'月間 '!AD35) | AF18: =IF('月間 '!AF19="","",'月間 '!AF19) | AG18: =IF('月間 '!AG19="","",'月間 '!AG19) | AH18: =IF('月間 '!AH19="","",'月間 '!AH19) | AI18: =IF('月間 '!AI19="","",'月間 '!AI19) -> 1/5日通院 | AJ18: =マスタ!$E$6-'３月月間(乗務員用）'!AK18 -> 23 | AK18: =COUNTIFS(C18:AH18,"✕")+COUNTIFS(C18:AH18,"修理")+COUNTIFS(C18:AH18,"車検")+COUNTIFS(C18:AH18,"研修") -> 8
A19: 【1693】鈴木 富雄 | C19: 苛性 | D19: =IF('月間 '!D20="","",'月間 '!D20) | E19: =IF('月間 '!E20="","",'月間 '!E20) | F19: =IF('月間 '!F20="","",'月間 '!F20) | G19: =IF('月間 '!G20="","",'月間 '!G20) | H19: =IF('月間 '!H20="","",'月間 '!H20) | I19: =IF('月間 '!I20="","",'月間 '!I20) | J19: =IF('月間 '!J20="","",'月間 '!J20) | K19: =IF('月間 '!K20="","",'月間 '!K20) | ... AI19: =IF('月間 '!AI20="","",'月間 '!AI20) | AJ19: =マスタ!$E$6-'３月月間(乗務員用）'!AK19 -> 31 | AK19: =COUNTIFS(C19:AH19,"✕")+COUNTIFS(C19:AH19,"修理")+COUNTIFS(C19:AH19,"車検")+COUNTIFS(C19:AH19,"研修") -> 0
A20: 【3640】大平 正勝 | C20: 苛性 | D20: =IF('月間 '!D21="","",'月間 '!D21) -> ✕ | E20: =IF('月間 '!E21="","",'月間 '!E21) -> ✕ | F20: =IF('月間 '!F21="","",'月間 '!F21) -> ✕ | G20: =IF('月間 '!G21="","",'月間 '!G21) -> ✕ | H20: =IF('月間 '!H21="","",'月間 '!H21) -> ✕ | I20: =IF('月間 '!I21="","",'月間 '!I21) -> ✕ | J20: =IF('月間 '!J21="","",'月間 '!J21) -> ✕ | K20: =IF('月間 '!K21="","",'月間 '!K21) -> ✕ | ... AI20: =IF('月間 '!AI21="","",'月間 '!AI21) -> 眼病療養中 | AJ20: =マスタ!$E$6-'３月月間(乗務員用）'!AK20 -> 0 | AK20: =COUNTIFS(D20:AH20,"✕")+COUNTIFS(D20:AH20,"出荷無")+COUNTIFS(D20:AH20,"発注無")+COUNTIFS(D20:AH20,"修理")+COUNTIFS(D20:AH20,"車検") -> 31
A21: 【643】荒木 正朋 | C21: 苛性 | D21: =IF('月間 '!D22="","",'月間 '!D22) -> ✕ | E21: =IF('月間 '!E22="","",'月間 '!E22) -> ✕ | F21: =IF('月間 '!F22="","",'月間 '!F22) -> 2401 | G21: =IF('月間 '!G22="","",'月間 '!G22) -> ✕ | H21: =IF('月間 '!H22="","",'月間 '!H22) -> 2401 | I21: =IF('月間 '!I22="","",'月間 '!I22) -> 2401 | J21: =IF('月間 '!J22="","",'月間 '!J22) -> 2401 | K21: =IF('月間 '!K22="","",'月間 '!K22) -> 2401 | ... AI21: =IF('月間 '!AI22="","",'月間 '!AI22) | AJ21: =マスタ!$E$6-'３月月間(乗務員用）'!AK21 -> 25 | AK21: =COUNTIFS(C21:AH21,"✕")+COUNTIFS(C21:AH21,"修理")+COUNTIFS(C21:AH21,"車検")+COUNTIFS(C21:AH21,"研修") -> 6
A22: 吉田 哲司 | C22: 苛性 | D22: =IF('月間 '!D23="","",'月間 '!D23) -> ✕ | E22: =IF('月間 '!E23="","",'月間 '!E23) -> 19 | F22: =IF('月間 '!F23="","",'月間 '!F23) -> ✕ | G22: =IF('月間 '!#REF!="","",'月間 '!#REF!) -> #REF! | H22: =IF('月間 '!H23="","",'月間 '!H23) -> 3640 | I22: =IF('月間 '!I23="","",'月間 '!I23) -> 19 | J22: =IF('月間 '!J23="","",'月間 '!J23) -> 19 | K22: =IF('月間 '!K23="","",'月間 '!K23) -> 19 | L22: =IF('月間 '!L23="","",'月間 '!L23) -> 19 | M22: =IF('月間 '!M23="","",'月間 '!M23) -> 1136 | N22: =IF('月間 '!N23="","",'月間 '!N23) -> 384 | O22: =IF('月間 '!O23="","",'月間 '!O23) -> 384 | ... AI22: =IF('月間 '!AI23="","",'月間 '!AI23) | AJ22: =マスタ!$E$6-'３月月間(乗務員用）'!AK22 -> 27 | AK22: =COUNTIFS(D22:AH22,"✕")+COUNTIFS(D22:AH22,"出荷無")+COUNTIFS(D22:AH22,"発注無")+COUNTIFS(D22:AH22,"修理")+COUNTIFS(D22:AH22,"車検") -> 4
A23: 菊地 秀和 | C23: 苛性 | D23: =IF('月間 '!D24="","",'月間 '!D24) -> ✕ | E23: =IF('月間 '!E24="","",'月間 '!E24) -> 384 | F23: =IF('月間 '!F24="","",'月間 '!F24) -> 384 | G23: =IF('月間 '!G24="","",'月間 '!G24) -> ✕ | H23: =IF('月間 '!H24="","",'月間 '!H24) -> ✕ | I23: =IF('月間 '!I24="","",'月間 '!I24) -> 整備 | J23: =IF('月間 '!J24="","",'月間 '!J24) -> 643 | K23: =IF('月間 '!K24="","",'月間 '!K24) | ... AI23: =IF('月間 '!AI24="","",'月間 '!AI24) -> 1/5通院 | AJ23: =マスタ!$E$6-'３月月間(乗務員用）'!AK23 -> 25 | AK23: =COUNTIFS(D23:AH23,"✕")+COUNTIFS(D23:AH23,"出荷無")+COUNTIFS(D23:AH23,"発注無")+COUNTIFS(D23:AH23,"修理")+COUNTIFS(D23:AH23,"車検") -> 6
A24: 【1136】山口 豊 | C24: 苛性 | D24: =IF('月間 '!#REF!="","",'月間 '!#REF!) -> #REF! | E24: =IF('月間 '!#REF!="","",'月間 '!#REF!) -> #REF! | F24: =IF('月間 '!#REF!="","",'月間 '!#REF!) -> #REF! | G24: =IF('月間 '!#REF!="","",'月間 '!#REF!) -> #REF! | H24: =IF('月間 '!#REF!="","",'月間 '!#REF!) -> #REF! | I24: =IF('月間 '!#REF!="","",'月間 '!#REF!) -> #REF! | J24: =IF('月間 '!#REF!="","",'月間 '!#REF!) -> #REF! | K24: =IF('月間 '!#REF!="","",'月間 '!#REF!) -> #REF! | ... AI24: =IF('月間 '!#REF!="","",'月間 '!#REF!) -> #REF! | AJ24: =マスタ!$E$6-'３月月間(乗務員用）'!AK24 -> 31 | AK24: =COUNTIFS(D24:AH24,"✕")+COUNTIFS(D24:AH24,"出荷無")+COUNTIFS(D24:AH24,"発注無")+COUNTIFS(D24:AH24,"修理")+COUNTIFS(D24:AH24,"車検") -> 0
A25: 【154】齋藤 健一 | C25: 苛性 | D25: =IF('月間 '!D25="","",'月間 '!D25) -> ✕ | E25: =IF('月間 '!E25="","",'月間 '!E25) -> 1136 | F25: =IF('月間 '!F25="","",'月間 '!F25) -> 1170 | G25: =IF('月間 '!G25="","",'月間 '!G25) -> ✕ | H25: =IF('月間 '!H25="","",'月間 '!H25) -> 1136 | I25: =IF('月間 '!I25="","",'月間 '!I25) -> 1170 | J25: =IF('月間 '!J25="","",'月間 '!J25) -> 1170 | K25: =IF('月間 '!K25="","",'月間 '!K25) -> 1136 | ... AI25: =IF('月間 '!AI25="","",'月間 '!AI25) | AJ25: =マスタ!$E$6-'３月月間(乗務員用）'!AK25 -> 26 | AK25: =COUNTIFS(D25:AH25,"✕")+COUNTIFS(D25:AH25,"出荷無")+COUNTIFS(D25:AH25,"発注無")+COUNTIFS(D25:AH25,"修理")+COUNTIFS(D25:AH25,"車検") -> 5
A26: 【係長】雲藤 順 | C26: バンド 油 | D26: =IF('月間 '!D41="","",'月間 '!D41) -> ✕ | E26: =IF('月間 '!E41="","",'月間 '!E41) -> ✕ | F26: =IF('月間 '!F41="","",'月間 '!F41) -> ✕ | G26: =IF('月間 '!G41="","",'月間 '!G41) -> ✕ | H26: =IF('月間 '!H41="","",'月間 '!H41) -> 1170 | I26: =IF('月間 '!I41="","",'月間 '!I41) -> 530 | J26: =IF('月間 '!J41="","",'月間 '!J41) -> 530 | K26: =IF('月間 '!K41="","",'月間 '!K41) -> 1170 | ... AH26: =IF('月間 '!AH41="","",'月間 '!AH41) | AI26: =IF('月間 '!AI30="","",'月間 '!AI30) | AJ26: =マスタ!$E$6-'３月月間(乗務員用）'!AK26 -> 23 | AK26: =COUNTIFS(C26:AH26,"✕")+COUNTIFS(C26:AH26,"修理")+COUNTIFS(C26:AH26,"車検")+COUNTIFS(C26:AH26,"研修") -> 8
A27: 神永 香織 | C27: バンド 油 | D27: =IF('月間 '!#REF!="","",'月間 '!#REF!) -> #REF! | E27: =IF('月間 '!#REF!="","",'月間 '!#REF!) -> #REF! | F27: =IF('月間 '!#REF!="","",'月間 '!#REF!) -> #REF! | G27: =IF('月間 '!#REF!="","",'月間 '!#REF!) -> #REF! | H27: =IF('月間 '!#REF!="","",'月間 '!#REF!) -> #REF! | I27: =IF('月間 '!#REF!="","",'月間 '!#REF!) -> #REF! | J27: =IF('月間 '!#REF!="","",'月間 '!#REF!) -> #REF! | K27: =IF('月間 '!#REF!="","",'月間 '!#REF!) -> #REF! | ... AH27: =IF('月間 '!#REF!="","",'月間 '!#REF!) -> #REF! | AI27: =IF('月間 '!AI31="","",'月間 '!AI31) | AJ27: =マスタ!$E$6-'３月月間(乗務員用）'!AK27 -> 31 | AK27: =COUNTIFS(C27:AH27,"✕")+COUNTIFS(C27:AH27,"修理")+COUNTIFS(C27:AH27,"車検")+COUNTIFS(C27:AH27,"研修") -> 0
A28: 松本 誠治 | C28: バンド 油 | D28: =IF('月間 '!#REF!="","",'月間 '!#REF!) -> #REF! | E28: =IF('月間 '!#REF!="","",'月間 '!#REF!) -> #REF! | F28: =IF('月間 '!#REF!="","",'月間 '!#REF!) -> #REF! | G28: =IF('月間 '!#REF!="","",'月間 '!#REF!) -> #REF! | H28: =IF('月間 '!#REF!="","",'月間 '!#REF!) -> #REF! | I28: =IF('月間 '!#REF!="","",'月間 '!#REF!) -> #REF! | J28: =IF('月間 '!#REF!="","",'月間 '!#REF!) -> #REF! | K28: =IF('月間 '!#REF!="","",'月間 '!#REF!) -> #REF! | ... AH28: =IF('月間 '!#REF!="","",'月間 '!#REF!) -> #REF! | AI28: =IF('月間 '!AI32="","",'月間 '!AI32) | AJ28: =マスタ!$E$6-'３月月間(乗務員用）'!AK28 -> 31 | AK28: =COUNTIFS(C28:AH28,"✕")+COUNTIFS(C28:AH28,"修理")+COUNTIFS(C28:AH28,"車検")+COUNTIFS(C28:AH28,"研修") -> 0
A29: 渡邊 晃弘 | C29: バンド 油 | D29: =IF('月間 '!#REF!="","",'月間 '!#REF!) -> #REF! | E29: =IF('月間 '!#REF!="","",'月間 '!#REF!) -> #REF! | F29: =IF('月間 '!#REF!="","",'月間 '!#REF!) -> #REF! | G29: =IF('月間 '!#REF!="","",'月間 '!#REF!) -> #REF! | H29: =IF('月間 '!#REF!="","",'月間 '!#REF!) -> #REF! | I29: =IF('月間 '!#REF!="","",'月間 '!#REF!) -> #REF! | J29: =IF('月間 '!#REF!="","",'月間 '!#REF!) -> #REF! | K29: =IF('月間 '!#REF!="","",'月間 '!#REF!) -> #REF! | ... AH29: =IF('月間 '!#REF!="","",'月間 '!#REF!) -> #REF! | AI29: =IF('月間 '!AI33="","",'月間 '!AI33) | AJ29: =マスタ!$E$6-'３月月間(乗務員用）'!AK29 -> 31 | AK29: =COUNTIFS(C29:AH29,"✕")+COUNTIFS(C29:AH29,"修理")+COUNTIFS(C29:AH29,"車検")+COUNTIFS(C29:AH29,"研修") -> 0
A30: ヘルプ①：齋藤（秀） | C30: バンド 油 | D30: =IF('月間 '!#REF!="","",'月間 '!#REF!) -> #REF! | E30: =IF('月間 '!#REF!="","",'月間 '!#REF!) -> #REF! | F30: =IF('月間 '!#REF!="","",'月間 '!#REF!) -> #REF! | G30: =IF('月間 '!#REF!="","",'月間 '!#REF!) -> #REF! | H30: =IF('月間 '!#REF!="","",'月間 '!#REF!) -> #REF! | I30: =IF('月間 '!#REF!="","",'月間 '!#REF!) -> #REF! | J30: =IF('月間 '!#REF!="","",'月間 '!#REF!) -> #REF! | K30: =IF('月間 '!#REF!="","",'月間 '!#REF!) -> #REF! | ... AH30: =IF('月間 '!#REF!="","",'月間 '!#REF!) -> #REF! | AJ30: =マスタ!$E$6-'月間 '!AK30 -> 25 | AK30: =COUNTIFS(C30:AH30,"✕")+COUNTIFS(C30:AH30,"修理")+COUNTIFS(C30:AH30,"車検")+COUNTIFS(C30:AH30,"研修") -> 0 | AL30: =AJ30+AM30 -> 25 | AM30: =COUNTIFS(D30:AH30,"✖") -> 0
A31: ヘルプ②：味戸 | C31: バンド 油 | D31: =IF('月間 '!#REF!="","",'月間 '!#REF!) -> #REF! | E31: =IF('月間 '!#REF!="","",'月間 '!#REF!) -> #REF! | F31: =IF('月間 '!#REF!="","",'月間 '!#REF!) -> #REF! | G31: =IF('月間 '!#REF!="","",'月間 '!#REF!) -> #REF! | H31: =IF('月間 '!#REF!="","",'月間 '!#REF!) -> #REF! | I31: =IF('月間 '!#REF!="","",'月間 '!#REF!) -> #REF! | J31: =IF('月間 '!#REF!="","",'月間 '!#REF!) -> #REF! | K31: =IF('月間 '!#REF!="","",'月間 '!#REF!) -> #REF! | ... AH31: =IF('月間 '!#REF!="","",'月間 '!#REF!) -> #REF! | AJ31: =マスタ!$E$6-'月間 '!AK31 -> 31 | AK31: =COUNTIFS(C31:AH31,"✕")+COUNTIFS(C31:AH31,"修理")+COUNTIFS(C31:AH31,"車検")+COUNTIFS(C31:AH31,"研修") -> 0 | AL31: =AJ31+AM31 -> 31 | AM31: =COUNTIFS(D31:AH31,"✖") -> 0
A32: 生産日：赤字 V-009納入：⑬ ⑫ プロセス(福島ゴム）：緑字 | L32: 緊急を除く、休日予定を月末までに記入下さい。 | AL32: =AJ32+AM32 -> 0 | AM32: =COUNTIFS(D32:AH32,"✖") -> 0
AL33: =AJ33+AM33 -> 0 | AM33: =COUNTIFS(D33:AH33,"✖") -> 0
AL34: =AJ34+AM34 -> 0 | AM34: =COUNTIFS(D34:AH34,"✖") -> 0
AL35: =AJ35+AM35 -> 0 | AM35: =COUNTIFS(D35:AH35,"✖") -> 0
AL36: =AJ36+AM36 -> 0 | AM36: =COUNTIFS(D36:AH36,"✖") -> 0
AL37: =AJ37+AM37 -> 0 | AM37: =COUNTIFS(D37:AH37,"✖") -> 0
AL38: =AJ38+AM38 -> 0 | AM38: =COUNTIFS(D38:AH38,"✖") -> 0

Sheet マスタ
B4: 祝日リスト
B5: 元日 | C5: 45658
B6: 成人の日 | C6: 45669 | E6: 31 | F6: 月カウント
B7: 建国記念日 | C7: 45699
B8: 振替休日
B9: 天皇誕生日 | C9: 45345 | E9: ✕ | F9: 休車
B10: 春分の日 | C10: 45371 | E10: 出荷なし | F10: 配送のみで宵積みなし
B11: 昭和の日 | C11: 45411 | E11: 発注なし | F11: オーダーがない
B12: 憲法記念日 | C12: 45415 | E12: 修理
B13: みどりの日 | E13: 車検
B14: こどもの日 | E14: 開放
B15: 振替休日 | C15: 45418 | E15: 洗浄
B16: 海の日 | C16: 45488 | E16: 宵積のみ
B17: 山の日 | C17: 45515 | E17: 研修
B18: 振替休日 | C18: 45516 | E18: 故障
B19: 敬老の日 | C19: 45551 | E19: 健康診断
B20: 秋分の日 | C20: 45557
B21: 振替休日 | C21: 45558
B22: スポーツの日 | C22: 45579
B23: 文化の日 | C23: 45599
B24: 振替休日 | C24: 45600
B25: 勤労感謝の日 | C25: 45619

Sheet Sheet2
A1: 氏 名 | F1: 回収日(質問票) | J1: 備 考
A2: 渡邊 浩司 | F2: 45154 | J2: 予約時間 ： 9：00
A3: 山口 豊 | F3: 45154 | J3: 予約時間 ： 9：20
A4: 小沼 康 | F4: 45155 | J4: 予約時間 ： 9：00
A5: 吉田 哲司 | F5: 45155 | J5: 予約時間 ： 9：20
A6: 鵜沼 芳昭 | F6: 45156 | J6: 予約時間 ： 8：40
A7: 菊地 秀和 | F7: 45156 | J7: 予約時間 ： 9：00
A8: 渡邉 進一 | F8: 45159 | J8: 予約時間 ： 9：00
A9: 小林 啓一 | F9: 45159 | J9: 予約時間 ： 9：40
A10: 鈴木 浩明 | F10: 45160 | J10: 予約時間 ： 8：40
A11: 齋藤 健一 | F11: 45160 | J11: 予約時間 ： 9：00
A12: 斎藤 秀行 | F12: 45161 | J12: 予約時間 ： 8：30
A13: 荒木 正朋 | F13: 45161 | J13: 予約時間 ： 8：40
... A28: 雲藤 順 | F28: 45174 | J28: 予約時間 ： 9：20
